Workbook

Sheet Schedule
A1: Date | B1: Day | C1: Start | D1: End | E1: Session | F1: Topic | G1: Instructor | H1: Where | I1: Note
A2: 46312 | B2: =TEXT(A2,"ddd") -> Sat | C2: 0.375 | D2: 0.54166667 | E2: Weekend AM | F2: Opening Ceremony · Practice · Principles of Vinyasa & Surya Namaskar | G2: Taq | H2: In studio
A3: 46312 | B3: =TEXT(A3,"ddd") -> Sat | C3: 0.58333333 | D3: 0.75 | E3: Weekend PM | F3: Techniques: Surya A | G3: Taq | H3: In studio
A4: 46312 | B4: =TEXT(A4,"ddd") -> Sat | C4: 0.71875 | E4: Weekend PM | F4: Orientation Pt 1 | G4: Mitch | H4: In studio | I4: Within PM block
A5: 46313 | B5: =TEXT(A5,"ddd") -> Sun | C5: 0.375 | D5: 0.54166667 | E5: Weekend AM | F5: Practice · Techniques: Surya B | G5: Mitch | H5: In studio
A6: 46313 | B6: =TEXT(A6,"ddd") -> Sun | C6: 0.58333333 | D6: 0.75 | E6: Weekend PM | F6: Techniques: Surya A & B | G6: Jeffrey | H6: In studio
A7: 46314 | B7: =TEXT(A7,"ddd") -> Mon | C7: 0.79166667 | D7: 0.83333333 | E7: Mon Check-In | F7: Orientation Pt 2 | G7: Taq | H7: Online
A8: 46315 | B8: =TEXT(A8,"ddd") -> Tue | C8: 0.79166667 | D8: 0.83333333 | E8: Tue Meditation | F8: Meditation: 3-Part | G8: Lauren | H8: Online
A9: 46317 | B9: =TEXT(A9,"ddd") -> Thu | C9: 0.8125 | D9: 0.89583333 | E9: Thu Lecture | F9: History & Ethics Part One | G9: Jeffrey | H9: Online | I9: Some Thursdays in studio — TBD in original
A10: 46318 | B10: =TEXT(A10,"ddd") -> Fri | C10: 0.75 | D10: 0.8125 | E10: Fri Asana Lab | F10: Asana Lab Master Class | G10: Mitch | H10: In studio
A11: 46319 | B11: =TEXT(A11,"ddd") -> Sat | C11: 0.375 | D11: 0.54166667 | E11: Weekend AM | F11: Practice · Techniques: Standing Poses | G11: Taq | H11: In studio
A12: 46319 | B12: =TEXT(A12,"ddd") -> Sat | C12: 0.58333333 | D12: 0.75 | E12: Weekend PM | F12: Practicum: Surya A & Surya B | G12: Mitch | H12: In studio
A13: 46320 | B13: =TEXT(A13,"ddd") -> Sun | C13: 0.375 | D13: 0.54166667 | E13: Weekend AM | F13: Practice · Techniques: Forward Folds | G13: Mitch | H13: In studio
A14: 46320 | B14: =TEXT(A14,"ddd") -> Sun | C14: 0.58333333 | D14: 0.75 | E14: Weekend PM | F14: Practicum: Standing Poses & Forward Folds | G14: Jeffrey | H14: In studio
A15: 46322 | B15: =TEXT(A15,"ddd") -> Tue | C15: 0.79166667 | D15: 0.83333333 | E15: Tue Meditation | F15: Meditation: B/L | G15: Lauren | H15: Online
A16: 46324 | B16: =TEXT(A16,"ddd") -> Thu | C16: 0.8125 | D16: 0.89583333 | E16: Thu Lecture | F16: Yoga Sutra | G16: Lauren | H16: Online | I16: Some Thursdays in studio — TBD in original
A17: 46325 | B17: =TEXT(A17,"ddd") -> Fri | C17: 0.75 | D17: 0.8125 | E17: Fri Asana Lab | F17: Asana Lab Master Class | G17: Jeffrey | H17: In studio
A18: 46326 | B18: =TEXT(A18,"ddd") -> Sat | C18: 0.375 | D18: 0.54166667 | E18: Weekend AM | F18: Practice · Techniques: Twists | G18: Taq | H18: In studio
A19: 46326 | B19: =TEXT(A19,"ddd") -> Sat | C19: 0.58333333 | D19: 0.75 | E19: Weekend PM | F19: Techniques: Backbends | G19: Mitch | H19: In studio
A20: 46327 | B20: =TEXT(A20,"ddd") -> Sun | C20: 0.375 | D20: 0.54166667 | E20: Weekend AM | F20: Practice · Practicum: Twists | G20: Becca | H20: In studio
A21: 46327 | B21: =TEXT(A21,"ddd") -> Sun | C21: 0.58333333 | D21: 0.75 | E21: Weekend PM | F21: Techniques: Hip Opening · Practicum: Backbends | G21: Mitch | H21: In studio
A22: 46329 | B22: =TEXT(A22,"ddd") -> Tue | C22: 0.79166667 | D22: 0.83333333 | E22: Tue Meditation | F22: Meditation: So Hum | G22: Lauren | H22: Online
A23: 46331 | B23: =TEXT(A23,"ddd") -> Thu | C23: 0.8125 | D23: 0.89583333 | E23: Thu Lecture | F23: Pranayama Part One | G23: Jeffrey | H23: Online | I23: Some Thursdays in studio — TBD in original
A24: 46332 | B24: =TEXT(A24,"ddd") -> Fri | C24: 0.75 | D24: 0.8125 | E24: Fri Asana Lab | F24: Asana Lab Master Class | G24: Mitch | H24: In studio
A25: 46336 | B25: =TEXT(A25,"ddd") -> Tue | C25: 0.79166667 | D25: 0.83333333 | E25: Tue Meditation | F25: Meditation: Amma | G25: Lauren | H25: Online
A26: 46338 | B26: =TEXT(A26,"ddd") -> Thu | C26: 0.8125 | D26: 0.89583333 | E26: Thu Lecture | F26: History & Ethics Part Two | G26: Jeffrey | H26: Online | I26: Some Thursdays in studio — TBD in original
A27: 46339 | B27: =TEXT(A27,"ddd") -> Fri | C27: 0.75 | D27: 0.8125 | E27: Fri Asana Lab | F27: Asana Lab Master Class | G27: Becca | H27: In studio
A28: 46340 | B28: =TEXT(A28,"ddd") -> Sat | C28: 0.375 | D28: 0.54166667 | E28: Weekend AM | F28: Practice · Subtle Body | G28: Lauren | H28: In studio
A29: 46340 | B29: =TEXT(A29,"ddd") -> Sat | C29: 0.58333333 | D29: 0.75 | E29: Weekend PM | F29: Subtle Body | G29: Lauren | H29: In studio
A30: 46341 | B30: =TEXT(A30,"ddd") -> Sun | C30: 0.375 | D30: 0.54166667 | E30: Weekend AM | F30: Practice · Practicum: Hip Opening | G30: Becca | H30: In studio
A31: 46341 | B31: =TEXT(A31,"ddd") -> Sun | C31: 0.58333333 | D31: 0.75 | E31: Weekend PM | F31: Techniques: Leg Balance | G31: Taq | H31: In studio
A32: 46342 | B32: =TEXT(A32,"ddd") -> Mon | C32: 0.79166667 | D32: 0.83333333 | E32: Mon Check-In | F32: Check-In | G32: Taq | H32: Online
A33: 46343 | B33: =TEXT(A33,"ddd") -> Tue | C33: 0.79166667 | D33: 0.83333333 | E33: Tue Meditation | F33: Meditation: Sa Ta Na Ma | G33: Lauren | H33: Online
A34: 46345 | B34: =TEXT(A34,"ddd") -> Thu | C34: 0.8125 | D34: 0.89583333 | E34: Thu Lecture | F34: Pranayama Part Two | G34: Jeffrey | H34: Online | I34: Some Thursdays in studio — TBD in original
A35: 46346 | B35: =TEXT(A35,"ddd") -> Fri | C35: 0.75 | D35: 0.8125 | E35: Fri Asana Lab | F35: Asana Lab Master Class | G35: Jeffrey | H35: In studio
A36: 46350 | B36: =TEXT(A36,"ddd") -> Tue | C36: 0.79166667 | D36: 0.83333333 | E36: Tue Meditation | F36: Meditation: Mindfulness | G36: Lauren | H36: Online
A37: 46357 | B37: =TEXT(A37,"ddd") -> Tue | C37: 0.79166667 | D37: 0.83333333 | E37: Tue Meditation | F37: Meditation: Gita · Japa | G37: Lauren | H37: Online
A38: 46359 | B38: =TEXT(A38,"ddd") -> Thu | C38: 0.8125 | D38: 0.89583333 | E38: Thu Lecture | F38: Ayurveda | G38: Lauren | H38: Online | I38: Some Thursdays in studio — TBD in original
A39: 46360 | B39: =TEXT(A39,"ddd") -> Fri | C39: 0.75 | D39: 0.8125 | E39: Fri Asana Lab | F39: Asana Lab Master Class | G39: Mitch | H39: In studio
A40: 46361 | B40: =TEXT(A40,"ddd") -> Sat | C40: 0.375 | D40: 0.54166667 | E40: Weekend AM | F40: Practice · Sequencing One: Warm-Up Category | G40: Jeffrey | H40: In studio
...

Sheet Calendar
A1: Week of | B1: Mon | C1: Tue | D1: Wed | E1: Thu | F1: Fri | G1: Sat | H1: Sun
A2: 46307 | G2: 9 Opening Ceremony · Practice · Principles of Vinyasa & Surya Namaskar (Taq) 2 Techniques: Surya A (Taq) 5:15 Orientation Pt 1 (Mitch) | H2: 9 Practice · Techniques: Surya B (Mitch) 2 Techniques: Surya A & B (Jeffrey)
A3: 46314 | B3: 7 Orientation Pt 2 (Taq) | C3: 7 3-Part (Lauren) | E3: 7:30 History & Ethics Part One (Jeffrey) | F3: 6 Asana Lab Master Class (Mitch) | G3: 9 Practice · Techniques: Standing Poses (Taq) 2 Practicum: Surya A & Surya B (Mitch) | H3: 9 Practice · Techniques: Forward Folds (Mitch) 2 Practicum: Standing Poses & Forward Folds (Jeffrey)
A4: 46321 | C4: 7 B/L (Lauren) | E4: 7:30 Yoga Sutra (Lauren) | F4: 6 Asana Lab Master Class (Jeffrey) | G4: 9 Practice · Techniques: Twists (Taq) 2 Techniques: Backbends (Mitch) | H4: 9 Practice · Practicum: Twists (Becca) 2 Techniques: Hip Opening · Practicum: Backbends (Mitch)
A5: 46328 | C5: 7 So Hum (Lauren) | E5: 7:30 Pranayama Part One (Jeffrey) | F5: 6 Asana Lab Master Class (Mitch)
A6: 46335 | C6: 7 Amma (Lauren) | E6: 7:30 History & Ethics Part Two (Jeffrey) | F6: 6 Asana Lab Master Class (Becca) | G6: 9 Practice · Subtle Body (Lauren) 2 Subtle Body (Lauren) | H6: 9 Practice · Practicum: Hip Opening (Becca) 2 Techniques: Leg Balance (Taq)
A7: 46342 | B7: 7 Check-In (Taq) | C7: 7 Sa Ta Na Ma (Lauren) | E7: 7:30 Pranayama Part Two (Jeffrey) | F7: 6 Asana Lab Master Class (Jeffrey)
A8: 46349 | C8: 7 Mindfulness (Lauren)
A9: 46356 | C9: 7 Gita · Japa (Lauren) | E9: 7:30 Ayurveda (Lauren) | F9: 6 Asana Lab Master Class (Mitch) | G9: 9 Practice · Sequencing One: Warm-Up Category (Jeffrey) 2 Anatomy Part One (Taq) | H9: 9 Practice · Techniques: Arm Balance (Mitch) 2 Techniques: Inversion (Becca)
A10: 46363 | C10: 7 Gita · Chakra (Lauren) | E10: 7:30 Intro to Yin (Mitch) | F10: 6 Asana Lab Master Class (Becca) | G10: 9 Practice · Practicum: Leg Balance & Arm Balance (Taq) 2 Anatomy Part Two (Taq) | H10: 9 Practice · Sequencing Two: Peak (Jeffrey) 2 Practicum: Inversions & Final Prep (Mitch)
A11: 46370 | B11: 7 Check-In (Taq) | C11: 7 Gita · Japa (Lauren) | E11: 7:30 Anatomy Review (Taq) | F11: 6 Asana Lab Master Class (Jeffrey)
A12: 46377
A13: 46384
A14: 46391 | B14: 7 Certification (Taq) | C14: 7 Gita · Empty Bowl (Lauren) | E14: 7:30 Business of Yoga (Mitch) | F14: 6 Asana Lab Master Class (Mitch) | G14: 9 Presentations (Mitch & Taq) 2 Yoga East Exam · DEI (Taq) | H14: 9 Presentations (Taq & Mitch) 2 Graduation Ceremony (Taq)
A16: Key | B16: Weekend AM | C16: Weekend PM | D16: Mon Check-In | E16: Tue Meditation | F16: Thu Lecture | G16: Fri Asana Lab

Sheet By Instructor
A1: Instructor | B1: Weekend AM | C1: Weekend PM | D1: Mon Check-In | E1: Tue Meditation | F1: Thu Lecture | G1: Fri Asana Lab | H1: Total
A2: Taq | B2: =COUNTIFS(Schedule!$G$2:$G$62,"*Taq*",Schedule!$E$2:$E$62,"Weekend AM") -> 6 | C2: =COUNTIFS(Schedule!$G$2:$G$62,"*Taq*",Schedule!$E$2:$E$62,"Weekend PM") -> 6 | D2: =COUNTIFS(Schedule!$G$2:$G$62,"*Taq*",Schedule!$E$2:$E$62,"Mon Check-In") -> 4 | E2: =COUNTIFS(Schedule!$G$2:$G$62,"*Taq*",Schedule!$E$2:$E$62,"Tue Meditation") -> 0 | F2: =COUNTIFS(Schedule!$G$2:$G$62,"*Taq*",Schedule!$E$2:$E$62,"Thu Lecture") -> 1 | G2: =COUNTIFS(Schedule!$G$2:$G$62,"*Taq*",Schedule!$E$2:$E$62,"Fri Asana Lab") -> 0 | H2: =SUM(B2:G2) -> 17
A3: Mitch | B3: =COUNTIFS(Schedule!$G$2:$G$62,"*Mitch*",Schedule!$E$2:$E$62,"Weekend AM") -> 5 | C3: =COUNTIFS(Schedule!$G$2:$G$62,"*Mitch*",Schedule!$E$2:$E$62,"Weekend PM") -> 5 | D3: =COUNTIFS(Schedule!$G$2:$G$62,"*Mitch*",Schedule!$E$2:$E$62,"Mon Check-In") -> 0 | E3: =COUNTIFS(Schedule!$G$2:$G$62,"*Mitch*",Schedule!$E$2:$E$62,"Tue Meditation") -> 0 | F3: =COUNTIFS(Schedule!$G$2:$G$62,"*Mitch*",Schedule!$E$2:$E$62,"Thu Lecture") -> 2 | G3: =COUNTIFS(Schedule!$G$2:$G$62,"*Mitch*",Schedule!$E$2:$E$62,"Fri Asana Lab") -> 4 | H3: =SUM(B3:G3) -> 16
A4: Jeffrey | B4: =COUNTIFS(Schedule!$G$2:$G$62,"*Jeffrey*",Schedule!$E$2:$E$62,"Weekend AM") -> 2 | C4: =COUNTIFS(Schedule!$G$2:$G$62,"*Jeffrey*",Schedule!$E$2:$E$62,"Weekend PM") -> 2 | D4: =COUNTIFS(Schedule!$G$2:$G$62,"*Jeffrey*",Schedule!$E$2:$E$62,"Mon Check-In") -> 0 | E4: =COUNTIFS(Schedule!$G$2:$G$62,"*Jeffrey*",Schedule!$E$2:$E$62,"Tue Meditation") -> 0 | F4: =COUNTIFS(Schedule!$G$2:$G$62,"*Jeffrey*",Schedule!$E$2:$E$62,"Thu Lecture") -> 4 | G4: =COUNTIFS(Schedule!$G$2:$G$62,"*Jeffrey*",Schedule!$E$2:$E$62,"Fri Asana Lab") -> 3 | H4: =SUM(B4:G4) -> 11
A5: Becca | B5: =COUNTIFS(Schedule!$G$2:$G$62,"*Becca*",Schedule!$E$2:$E$62,"Weekend AM") -> 2 | C5: =COUNTIFS(Schedule!$G$2:$G$62,"*Becca*",Schedule!$E$2:$E$62,"Weekend PM") -> 1 | D5: =COUNTIFS(Schedule!$G$2:$G$62,"*Becca*",Schedule!$E$2:$E$62,"Mon Check-In") -> 0 | E5: =COUNTIFS(Schedule!$G$2:$G$62,"*Becca*",Schedule!$E$2:$E$62,"Tue Meditation") -> 0 | F5: =COUNTIFS(Schedule!$G$2:$G$62,"*Becca*",Schedule!$E$2:$E$62,"Thu Lecture") -> 0 | G5: =COUNTIFS(Schedule!$G$2:$G$62,"*Becca*",Schedule!$E$2:$E$62,"Fri Asana Lab") -> 2 | H5: =SUM(B5:G5) -> 5
A6: Lauren | B6: =COUNTIFS(Schedule!$G$2:$G$62,"*Lauren*",Schedule!$E$2:$E$62,"Weekend AM") -> 1 | C6: =COUNTIFS(Schedule!$G$2:$G$62,"*Lauren*",Schedule!$E$2:$E$62,"Weekend PM") -> 1 | D6: =COUNTIFS(Schedule!$G$2:$G$62,"*Lauren*",Schedule!$E$2:$E$62,"Mon Check-In") -> 0 | E6: =COUNTIFS(Schedule!$G$2:$G$62,"*Lauren*",Schedule!$E$2:$E$62,"Tue Meditation") -> 10 | F6: =COUNTIFS(Schedule!$G$2:$G$62,"*Lauren*",Schedule!$E$2:$E$62,"Thu Lecture") -> 2 | G6: =COUNTIFS(Schedule!$G$2:$G$62,"*Lauren*",Schedule!$E$2:$E$62,"Fri Asana Lab") -> 0 | H6: =SUM(B6:G6) -> 14
A8: Co-taught sessions (e.g. Mitch & Taq) count for each instructor.
